Workbook

Sheet ASIGNACIÓN
B1: Nro | C1: EMPRESA | D1: F. ENSAMBLE | E1: DNI | F1: APELLIDOS | G1: NOMBRES | H1: MES | I1: AÑO | J1: DOSIMETRO | K1: DEVOL | L1: HP(10) (Lectura) | M1: HP(0.07) (Lectura) | N1: FONDO | O1: HP(10) (Final) | P1: HP(0.07) (Final) | Q1: INFO QR | T1: SI
B2: 1 | C2: CENTRO DE DIAGNOSTICO MEDICO CHICLAYO S.A.C | D2: 45135 | E2: 76768136 | F2: VASQUEZ GARCIA | G2: CESAR RONALDO | H2: AGOSTO | I2: 2023 | J2: 1952 | K2: SI | L2: 0.1431 | M2: 0.144 | O2: =ASIGNACIÓN!$L2-ASIGNACIÓN!$N2 -> 0.1431 | P2: =ASIGNACIÓN!$M2-ASIGNACIÓN!$N2 -> 0.144 | Q2: =+CONCATENATE(ASIGNACIÓN!$F2," ",ASIGNACIÓN!$G2," ",ASIGNACIÓN!$H2," ",ASIGNACIÓN!$I2," ",ASIGNACIÓN!$J2) -> VASQUEZ GARCIA CESAR RONALDO AGOSTO 2023 1952 | T2: NO
B3: 2 | C3: CENTRO DE DIAGNOSTICO MEDICO CHICLAYO S.A.C | D3: 45135 | E3: 75706614 | F3: GORDILLO TARRILLO | G3: OSCAR | H3: AGOSTO | I3: 2023 | J3: 1917 | K3: SI | L3: 0.1341 | M3: 0.1396 | O3: =ASIGNACIÓN!$L3-ASIGNACIÓN!$N3 -> 0.1341 | P3: =ASIGNACIÓN!$M3-ASIGNACIÓN!$N3 -> 0.1396 | Q3: =+CONCATENATE(ASIGNACIÓN!$F3," ",ASIGNACIÓN!$G3," ",ASIGNACIÓN!$H3," ",ASIGNACIÓN!$I3," ",ASIGNACIÓN!$J3) -> GORDILLO TARRILLO OSCAR AGOSTO 2023 1917
B4: 3 | C4: CLINICA VIRGEN DEL PILAR S.C.R.L. | D4: 45135 | E4: 241861 | F4: LOPEZ VALENCIA | G4: ANGEL EDISON | H4: AGOSTO | I4: 2023 | J4: 1851 | K4: SI | L4: 0.1466 | M4: 0.14 | O4: =ASIGNACIÓN!$L4-ASIGNACIÓN!$N4 -> 0.1466 | P4: =ASIGNACIÓN!$M4-ASIGNACIÓN!$N4 -> 0.14 | Q4: =+CONCATENATE(ASIGNACIÓN!$F4," ",ASIGNACIÓN!$G4," ",ASIGNACIÓN!$H4," ",ASIGNACIÓN!$I4," ",ASIGNACIÓN!$J4) -> LOPEZ VALENCIA ANGEL EDISON AGOSTO 2023 1851
B5: 4 | C5: CLINICA VIRGEN DEL PILAR S.C.R.L. | D5: 45135 | E5: 44057135 | F5: BAZAN GALLO | G5: DANNY | H5: AGOSTO | I5: 2023 | J5: 1484 | K5: SI | L5: 0.1488 | M5: 0.1496 | O5: =ASIGNACIÓN!$L5-ASIGNACIÓN!$N5 -> 0.1488 | P5: =ASIGNACIÓN!$M5-ASIGNACIÓN!$N5 -> 0.1496 | Q5: =+CONCATENATE(ASIGNACIÓN!$F5," ",ASIGNACIÓN!$G5," ",ASIGNACIÓN!$H5," ",ASIGNACIÓN!$I5," ",ASIGNACIÓN!$J5) -> BAZAN GALLO DANNY AGOSTO 2023 1484
B6: 5 | C6: DAVID LARREA | D6: 45146 | E6: 43554046 | F6: VIDAL GRAZA | G6: VERONICA | H6: AGOSTO | I6: 2023 | J6: 1871 | K6: SI | L6: 0.2838 | M6: 0.2704 | O6: =ASIGNACIÓN!$L6-ASIGNACIÓN!$N6 -> 0.2838 | P6: =ASIGNACIÓN!$M6-ASIGNACIÓN!$N6 -> 0.2704 | Q6: =+CONCATENATE(ASIGNACIÓN!$F6," ",ASIGNACIÓN!$G6," ",ASIGNACIÓN!$H6," ",ASIGNACIÓN!$I6," ",ASIGNACIÓN!$J6) -> VIDAL GRAZA VERONICA AGOSTO 2023 1871
B7: 6 | C7: DAVID LARREA | D7: 45135 | E7: 44284423 | F7: BAZAN MALASQUEZ | G7: MAYRA | H7: AGOSTO | I7: 2023 | J7: 2005 | K7: SI | L7: 0.2383 | M7: 0.2225 | O7: =ASIGNACIÓN!$L7-ASIGNACIÓN!$N7 -> 0.2383 | P7: =ASIGNACIÓN!$M7-ASIGNACIÓN!$N7 -> 0.2225 | Q7: =+CONCATENATE(ASIGNACIÓN!$F7," ",ASIGNACIÓN!$G7," ",ASIGNACIÓN!$H7," ",ASIGNACIÓN!$I7," ",ASIGNACIÓN!$J7) -> BAZAN MALASQUEZ MAYRA AGOSTO 2023 2005
B8: 7 | C8: DIAGNO SERVICIOS INTEGRALES S.A.C. | D8: 45135 | E8: 45257649 | F8: VALVERDE HURTADO | G8: DEYSI | H8: AGOSTO | I8: 2023 | J8: 1914 | K8: SI | L8: 0.1222 | M8: 0.1197 | O8: =ASIGNACIÓN!$L8-ASIGNACIÓN!$N8 -> 0.1222 | P8: =ASIGNACIÓN!$M8-ASIGNACIÓN!$N8 -> 0.1197 | Q8: =+CONCATENATE(ASIGNACIÓN!$F8," ",ASIGNACIÓN!$G8," ",ASIGNACIÓN!$H8," ",ASIGNACIÓN!$I8," ",ASIGNACIÓN!$J8) -> VALVERDE HURTADO DEYSI AGOSTO 2023 1914
B9: 8 | C9: DIAGNO SERVICIOS INTEGRALES S.A.C. | D9: 45135 | E9: 44546803 | F9: TTITO QUISPE | G9: JACKELINE VANESSA | H9: AGOSTO | I9: 2023 | J9: 1884 | K9: SI | L9: 0.1525 | M9: 0.1603 | O9: =ASIGNACIÓN!$L9-ASIGNACIÓN!$N9 -> 0.1525 | P9: =ASIGNACIÓN!$M9-ASIGNACIÓN!$N9 -> 0.1603 | Q9: =+CONCATENATE(ASIGNACIÓN!$F9," ",ASIGNACIÓN!$G9," ",ASIGNACIÓN!$H9," ",ASIGNACIÓN!$I9," ",ASIGNACIÓN!$J9) -> TTITO QUISPE JACKELINE VANESSA AGOSTO 2023 1884
B10: 9 | C10: DIAGNO SERVICIOS INTEGRALES S.A.C. | D10: 45135 | E10: 73379001 | F10: SANCHEZ MELCHOR | G10: EVELYN ANDREA | H10: AGOSTO | I10: 2023 | J10: 1468 | K10: SI | L10: 0.1325 | M10: 0.1322 | O10: =ASIGNACIÓN!$L10-ASIGNACIÓN!$N10 -> 0.1325 | P10: =ASIGNACIÓN!$M10-ASIGNACIÓN!$N10 -> 0.1322 | Q10: =+CONCATENATE(ASIGNACIÓN!$F10," ",ASIGNACIÓN!$G10," ",ASIGNACIÓN!$H10," ",ASIGNACIÓN!$I10," ",ASIGNACIÓN!$J10) -> SANCHEZ MELCHOR EVELYN ANDREA AGOSTO 2023 1468
B11: 10 | C11: DIAGNO SERVICIOS INTEGRALES S.A.C. | D11: 45135 | E11: 70477585 | F11: GAMARRA SANCHEZ | G11: JUAN AARON | H11: AGOSTO | I11: 2023 | J11: 1933 | K11: SI | L11: 0.3453 | M11: 0.3432 | O11: =ASIGNACIÓN!$L11-ASIGNACIÓN!$N11 -> 0.3453 | P11: =ASIGNACIÓN!$M11-ASIGNACIÓN!$N11 -> 0.3432 | Q11: =+CONCATENATE(ASIGNACIÓN!$F11," ",ASIGNACIÓN!$G11," ",ASIGNACIÓN!$H11," ",ASIGNACIÓN!$I11," ",ASIGNACIÓN!$J11) -> GAMARRA SANCHEZ JUAN AARON AGOSTO 2023 1933
B12: 11 | C12: DIAGNO SERVICIOS INTEGRALES S.A.C. | D12: 45135 | E12: 47945983 | F12: DAVILA VILLANELA | G12: LIZ KELLY | H12: AGOSTO | I12: 2023 | J12: 1882 | K12: SI | L12: 0.1403 | M12: 0.1314 | O12: =ASIGNACIÓN!$L12-ASIGNACIÓN!$N12 -> 0.1403 | P12: =ASIGNACIÓN!$M12-ASIGNACIÓN!$N12 -> 0.1314 | Q12: =+CONCATENATE(ASIGNACIÓN!$F12," ",ASIGNACIÓN!$G12," ",ASIGNACIÓN!$H12," ",ASIGNACIÓN!$I12," ",ASIGNACIÓN!$J12) -> DAVILA VILLANELA LIZ KELLY AGOSTO 2023 1882
B13: 12 | C13: DIAGNO SERVICIOS INTEGRALES S.A.C. | D13: 45135 | E13: 46459186 | F13: ARREDONDO CAMACHO | G13: MARIA DE LOS ANGELES | H13: AGOSTO | I13: 2023 | J13: 2021 | K13: SI | L13: 0.1362 | M13: 0.1362 | O13: =ASIGNACIÓN!$L13-ASIGNACIÓN!$N13 -> 0.1362 | P13: =ASIGNACIÓN!$M13-ASIGNACIÓN!$N13 -> 0.1362 | Q13: =+CONCATENATE(ASIGNACIÓN!$F13," ",ASIGNACIÓN!$G13," ",ASIGNACIÓN!$H13," ",ASIGNACIÓN!$I13," ",ASIGNACIÓN!$J13) -> ARREDONDO CAMACHO MARIA DE LOS ANGELES AGOSTO 2023 2021
B14: 13 | C14: FIS MED S.A.C. | D14: 45135 | E14: 75232436 | F14: SEGURA RIVERA | G14: EDUARDO PAOLO | H14: AGOSTO | I14: 2023 | J14: 1995 | K14: SI | L14: 0.1291 | M14: 0.1349 | O14: =ASIGNACIÓN!$L14-ASIGNACIÓN!$N14 -> 0.1291 | P14: =ASIGNACIÓN!$M14-ASIGNACIÓN!$N14 -> 0.1349 | Q14: =+CONCATENATE(ASIGNACIÓN!$F14," ",ASIGNACIÓN!$G14," ",ASIGNACIÓN!$H14," ",ASIGNACIÓN!$I14," ",ASIGNACIÓN!$J14) -> SEGURA RIVERA EDUARDO PAOLO AGOSTO 2023 1995
... B16: 15 | C16: FIS MED S.A.C. | D16: 45135 | E16: 19250109 | F16: MORA YENGLE | G16: BORIS | H16: AGOSTO | I16: 2023 | J16: 1721 | K16: SI | L16: 0.1405 | M16: 0.1356 | O16: =ASIGNACIÓN!$L16-ASIGNACIÓN!$N16 -> 0.1405 | P16: =ASIGNACIÓN!$M16-ASIGNACIÓN!$N16 -> 0.1356 | Q16: =+CONCATENATE(ASIGNACIÓN!$F16," ",ASIGNACIÓN!$G16," ",ASIGNACIÓN!$H16," ",ASIGNACIÓN!$I16," ",ASIGNACIÓN!$J16) -> MORA YENGLE BORIS AGOSTO 2023 1721
B17: 16 | C17: KAVELG S.A.C. | D17: 45135 | E17: 40349406 | F17: VELARDE LAM | G17: MARIA KATIA | H17: AGOSTO | I17: 2023 | J17: 1720 | K17: SI | L17: no tiene lectura | O17: =ASIGNACIÓN!$L17-ASIGNACIÓN!$N17 -> #VALUE! | P17: =ASIGNACIÓN!$M17-ASIGNACIÓN!$N17 -> 0 | Q17: =+CONCATENATE(ASIGNACIÓN!$F17," ",ASIGNACIÓN!$G17," ",ASIGNACIÓN!$H17," ",ASIGNACIÓN!$I17," ",ASIGNACIÓN!$J17) -> VELARDE LAM MARIA KATIA AGOSTO 2023 1720
B18: 17 | C18: MEDIMAGEN S.A.C. | D18: 45135 | E18: 49049071 | F18: RICALDI GAVIDIA | G18: KARINA | H18: AGOSTO | I18: 2023 | J18: 1870 | K18: SI | L18: 0.1356 | M18: 0.1315 | O18: =ASIGNACIÓN!$L18-ASIGNACIÓN!$N18 -> 0.1356 | P18: =ASIGNACIÓN!$M18-ASIGNACIÓN!$N18 -> 0.1315 | Q18: =+CONCATENATE(ASIGNACIÓN!$F18," ",ASIGNACIÓN!$G18," ",ASIGNACIÓN!$H18," ",ASIGNACIÓN!$I18," ",ASIGNACIÓN!$J18) -> RICALDI GAVIDIA KARINA AGOSTO 2023 1870
B19: 18 | C19: MEDIMAGEN S.A.C. | D19: 45135 | E19: 7250076 | F19: COCA NUÑEZ | G19: MIGUEL | H19: AGOSTO | I19: 2023 | J19: 1429 | K19: SI | L19: 0.1394 | M19: 0.1299 | O19: =ASIGNACIÓN!$L19-ASIGNACIÓN!$N19 -> 0.1394 | P19: =ASIGNACIÓN!$M19-ASIGNACIÓN!$N19 -> 0.1299 | Q19: =+CONCATENATE(ASIGNACIÓN!$F19," ",ASIGNACIÓN!$G19," ",ASIGNACIÓN!$H19," ",ASIGNACIÓN!$I19," ",ASIGNACIÓN!$J19) -> COCA NUÑEZ MIGUEL AGOSTO 2023 1429
B20: 459 | C20: PULSO CORPORACION MEDICA S.A.C. | D20: 30/11/2023 | E20: 7514845 | F20: COLQUI VALERIO | G20: MONICA | H20: DICIEMBRE | I20: 2023 | J20: 1779 | K20: NO | O20: =ASIGNACIÓN!$L20-ASIGNACIÓN!$N20 -> 0 | P20: =ASIGNACIÓN!$M20-ASIGNACIÓN!$N20 -> 0 | Q20: =+CONCATENATE(ASIGNACIÓN!$F20," ",ASIGNACIÓN!$G20," ",ASIGNACIÓN!$H20," ",ASIGNACIÓN!$I20," ",ASIGNACIÓN!$J20) -> COLQUI VALERIO MONICA DICIEMBRE 2023 1779
B21: 98 | C21: TERES SALUD E.I.R.L. | D21: 45135 | E21: 74208270 | F21: AGUILAR VALLE | G21: MAYRA ALEJANDRA | H21: DICIEMBRE | I21: 2023 | J21: 1993 | K21: SI | L21: 0.1335 | M21: 0.1216 | O21: =ASIGNACIÓN!$L21-ASIGNACIÓN!$N21 -> 0.1335 | P21: =ASIGNACIÓN!$M21-ASIGNACIÓN!$N21 -> 0.1216 | Q21: =+CONCATENATE(ASIGNACIÓN!$F21," ",ASIGNACIÓN!$G21," ",ASIGNACIÓN!$H21," ",ASIGNACIÓN!$I21," ",ASIGNACIÓN!$J21) -> AGUILAR VALLE MAYRA ALEJANDRA DICIEMBRE 2023 1993
B22: 437 | C22: PULSO CORPORACION MEDICA S.A.C. | D22: 18/11/2023 | E22: 46574816 | F22: ALVARADO CANOVA | G22: ANDRE MANUEL | H22: DICIEMBRE | I22: 2023 | J22: 1614 | K22: NO | O22: =ASIGNACIÓN!$L22-ASIGNACIÓN!$N22 -> 0 | P22: =ASIGNACIÓN!$M22-ASIGNACIÓN!$N22 -> 0 | Q22: =+CONCATENATE(ASIGNACIÓN!$F22," ",ASIGNACIÓN!$G22," ",ASIGNACIÓN!$H22," ",ASIGNACIÓN!$I22," ",ASIGNACIÓN!$J22) -> ALVARADO CANOVA ANDRE MANUEL DICIEMBRE 2023 1614
B23: 22 | C23: SOCIEDAD PEDIATRICA ESPECIALIZADA E.I.R.L. | D23: 45135 | E23: 21796702 | F23: MARROQUIN SAMANEZ | G23: JORGE ALCIDES | H23: AGOSTO | I23: 2023 | J23: 1733 | K23: SI | L23: 0.5064 | M23: 0.4769 | O23: =ASIGNACIÓN!$L23-ASIGNACIÓN!$N23 -> 0.5064 | P23: =ASIGNACIÓN!$M23-ASIGNACIÓN!$N23 -> 0.4769 | Q23: =+CONCATENATE(ASIGNACIÓN!$F23," ",ASIGNACIÓN!$G23," ",ASIGNACIÓN!$H23," ",ASIGNACIÓN!$I23," ",ASIGNACIÓN!$J23) -> MARROQUIN SAMANEZ JORGE ALCIDES AGOSTO 2023 1733
B24: 50 | C24: EPPS ESPECIALIDADES MEDICAS ONCOLABS E.I.R.L. | D24: 45255 | E24: 73415776 | F24: ARAUJO SALCEDO | G24: EDGAR OMAR | H24: DICIEMBRE | I24: 2023 | J24: 1587 | K24: SI | L24: 0.2098 | M24: 0.2159 | O24: =ASIGNACIÓN!$L24-ASIGNACIÓN!$N24 -> 0.2098 | P24: =ASIGNACIÓN!$M24-ASIGNACIÓN!$N24 -> 0.2159 | Q24: =+CONCATENATE(ASIGNACIÓN!$F24," ",ASIGNACIÓN!$G24," ",ASIGNACIÓN!$H24," ",ASIGNACIÓN!$I24," ",ASIGNACIÓN!$J24) -> ARAUJO SALCEDO EDGAR OMAR DICIEMBRE 2023 1587
B25: 34 | C25: DIAGNO SERVICIOS INTEGRALES S.A.C. | D25: 29/11/2023 | E25: 46459186 | F25: ARREDONDO CAMACHO | G25: MARIA DE LOS ANGELES | H25: DICIEMBRE | I25: 2023 | J25: 1810 | K25: SI | L25: 0.1298 | M25: 0.1358 | O25: =ASIGNACIÓN!$L25-ASIGNACIÓN!$N25 -> 0.1298 | P25: =ASIGNACIÓN!$M25-ASIGNACIÓN!$N25 -> 0.1358 | Q25: =+CONCATENATE(ASIGNACIÓN!$F25," ",ASIGNACIÓN!$G25," ",ASIGNACIÓN!$H25," ",ASIGNACIÓN!$I25," ",ASIGNACIÓN!$J25) -> ARREDONDO CAMACHO MARIA DE LOS ANGELES DICIEMBRE 2023 1810
B26: 79 | C26: PRIMCO | D26: 45255 | E26: 10543761 | F26: ARRIETA CABRERA | G26: EDUARDO | H26: DICIEMBRE | I26: 2023 | J26: 2002 | K26: SI | L26: 0.1335 | M26: 0.1266 | O26: =ASIGNACIÓN!$L26-ASIGNACIÓN!$N26 -> 0.1335 | P26: =ASIGNACIÓN!$M26-ASIGNACIÓN!$N26 -> 0.1266 | Q26: =+CONCATENATE(ASIGNACIÓN!$F26," ",ASIGNACIÓN!$G26," ",ASIGNACIÓN!$H26," ",ASIGNACIÓN!$I26," ",ASIGNACIÓN!$J26) -> ARRIETA CABRERA EDUARDO DICIEMBRE 2023 2002
B27: 49 | C27: DIAGNOSTICO MEDICO ESPECIALIZADO S.A.C. | D27: 29/11/2023 | E27: 77679579 | F27: ASTOCONDOR FUERTES | G27: FRANKLIN KEVIN | H27: DICIEMBRE | I27: 2023 | J27: 1341 | K27: SI | L27: 0.1325 | M27: 0.1167 | O27: =ASIGNACIÓN!$L27-ASIGNACIÓN!$N27 -> 0.1325 | P27: =ASIGNACIÓN!$M27-ASIGNACIÓN!$N27 -> 0.1167 | Q27: =+CONCATENATE(ASIGNACIÓN!$F27," ",ASIGNACIÓN!$G27," ",ASIGNACIÓN!$H27," ",ASIGNACIÓN!$I27," ",ASIGNACIÓN!$J27) -> ASTOCONDOR FUERTES FRANKLIN KEVIN DICIEMBRE 2023 1341
B28: 407 | C28: DAVID LARREA | D28: 45255 | E28: 44284423 | F28: BAZAN MALASQUEZ | G28: MAYRA | H28: DICIEMBRE | I28: 2023 | J28: 1958 | K28: SI | L28: 0.6699 | M28: 0.6159 | O28: =ASIGNACIÓN!$L28-ASIGNACIÓN!$N28 -> 0.6699 | P28: =ASIGNACIÓN!$M28-ASIGNACIÓN!$N28 -> 0.6159 | Q28: =+CONCATENATE(ASIGNACIÓN!$F28," ",ASIGNACIÓN!$G28," ",ASIGNACIÓN!$H28," ",ASIGNACIÓN!$I28," ",ASIGNACIÓN!$J28) -> BAZAN MALASQUEZ MAYRA DICIEMBRE 2023 1958
B29: 71 | C29: HOSPITAL METROPOLITANO S.A.C | D29: 45255 | E29: 46998527 | F29: BENITES AGAPITO | G29: ABIGAIL ESTEFANIA | H29: DICIEMBRE | I29: 2023 | J29: 1547 | K29: SI | L29: 0.1874 | M29: 0.1728 | O29: =ASIGNACIÓN!$L29-ASIGNACIÓN!$N29 -> 0.1874 | P29: =ASIGNACIÓN!$M29-ASIGNACIÓN!$N29 -> 0.1728 | Q29: =+CONCATENATE(ASIGNACIÓN!$F29," ",ASIGNACIÓN!$G29," ",ASIGNACIÓN!$H29," ",ASIGNACIÓN!$I29," ",ASIGNACIÓN!$J29) -> BENITES AGAPITO ABIGAIL ESTEFANIA DICIEMBRE 2023 1547
B30: 70 | C30: HOSPITAL METROPOLITANO S.A.C | D30: 45255 | E30: 76474272 | F30: CAJO RAMOS | G30: ROSA ELENA | H30: DICIEMBRE | I30: 2023 | J30: 1496 | K30: SI | L30: 0.2055 | M30: 0.1896 | O30: =ASIGNACIÓN!$L30-ASIGNACIÓN!$N30 -> 0.2055 | P30: =ASIGNACIÓN!$M30-ASIGNACIÓN!$N30 -> 0.1896 | Q30: =+CONCATENATE(ASIGNACIÓN!$F30," ",ASIGNACIÓN!$G30," ",ASIGNACIÓN!$H30," ",ASIGNACIÓN!$I30," ",ASIGNACIÓN!$J30) -> CAJO RAMOS ROSA ELENA DICIEMBRE 2023 1496
B31: 33 | C31: DIAGNO SERVICIOS INTEGRALES S.A.C. | D31: 45255 | E31: 70014224 | F31: CALDERON CERNA | G31: MARIA CRISTINA | H31: DICIEMBRE | I31: 2023 | J31: 1915 | K31: SI | L31: 0.1449 | M31: 0.1495 | O31: =ASIGNACIÓN!$L31-ASIGNACIÓN!$N31 -> 0.1449 | P31: =ASIGNACIÓN!$M31-ASIGNACIÓN!$N31 -> 0.1495 | Q31: =+CONCATENATE(ASIGNACIÓN!$F31," ",ASIGNACIÓN!$G31," ",ASIGNACIÓN!$H31," ",ASIGNACIÓN!$I31," ",ASIGNACIÓN!$J31) -> CALDERON CERNA MARIA CRISTINA DICIEMBRE 2023 1915
B32: 90 | C32: PULSO CORPORACION MEDICA S.A.C. | D32: 45255 | E32: 2487535 | F32: CAÑAS GAVIDIA | G32: MARYORY NATALY | H32: DICIEMBRE | I32: 2023 | J32: 1665 | K32: SI | L32: 0.292 | M32: 0.284 | O32: =ASIGNACIÓN!$L32-ASIGNACIÓN!$N32 -> 0.292 | P32: =ASIGNACIÓN!$M32-ASIGNACIÓN!$N32 -> 0.284 | Q32: =+CONCATENATE(ASIGNACIÓN!$F32," ",ASIGNACIÓN!$G32," ",ASIGNACIÓN!$H32," ",ASIGNACIÓN!$I32," ",ASIGNACIÓN!$J32) -> CAÑAS GAVIDIA MARYORY NATALY DICIEMBRE 2023 1665
B33: 96 | C33: TERES SALUD E.I.R.L. | D33: 45255 | E33: 70385995 | F33: CARDENAS OBREGON | G33: BETSY JAZMIN | H33: DICIEMBRE | I33: 2023 | J33: 1550 | K33: SI | L33: 0.1387 | M33: 0.1257 | O33: =ASIGNACIÓN!$L33-ASIGNACIÓN!$N33 -> 0.1387 | P33: =ASIGNACIÓN!$M33-ASIGNACIÓN!$N33 -> 0.1257 | Q33: =+CONCATENATE(ASIGNACIÓN!$F33," ",ASIGNACIÓN!$G33," ",ASIGNACIÓN!$H33," ",ASIGNACIÓN!$I33," ",ASIGNACIÓN!$J33) -> CARDENAS OBREGON BETSY JAZMIN DICIEMBRE 2023 1550
B34: 68 | C34: HOSPITAL METROPOLITANO S.A.C | D34: 45255 | E34: 16688726 | F34: CASTRO RAMIREZ | G34: HENRY | H34: DICIEMBRE | I34: 2023 | J34: 1571 | K34: SI | L34: 0.2097 | M34: 0.2077 | O34: =ASIGNACIÓN!$L34-ASIGNACIÓN!$N34 -> 0.2097 | P34: =ASIGNACIÓN!$M34-ASIGNACIÓN!$N34 -> 0.2077 | Q34: =+CONCATENATE(ASIGNACIÓN!$F34," ",ASIGNACIÓN!$G34," ",ASIGNACIÓN!$H34," ",ASIGNACIÓN!$I34," ",ASIGNACIÓN!$J34) -> CASTRO RAMIREZ HENRY DICIEMBRE 2023 1571
B35: 69 | C35: HOSPITAL METROPOLITANO S.A.C | D35: 45255 | E35: 16688726 | F35: CASTRO RAMIREZ | G35: HENRY | H35: DICIEMBRE | I35: 2023 | J35: 1672 | K35: SI | L35: 0.1973 | M35: 0.2173 | O35: =ASIGNACIÓN!$L35-ASIGNACIÓN!$N35 -> 0.1973 | P35: =ASIGNACIÓN!$M35-ASIGNACIÓN!$N35 -> 0.2173 | Q35: =+CONCATENATE(ASIGNACIÓN!$F35," ",ASIGNACIÓN!$G35," ",ASIGNACIÓN!$H35," ",ASIGNACIÓN!$I35," ",ASIGNACIÓN!$J35) -> CASTRO RAMIREZ HENRY DICIEMBRE 2023 1672
B36: 48 | C36: DIAGNOSTICO MEDICO ESPECIALIZADO S.A.C. | D36: 29/11/2023 | E36: 80458004 | F36: CHAVARRY BARRANTES | G36: VICTOR YOVANI | H36: DICIEMBRE | I36: 2023 | J36: 1501 | K36: SI | L36: 0.1564 | M36: 0.1573 | O36: =ASIGNACIÓN!$L36-ASIGNACIÓN!$N36 -> 0.1564 | P36: =ASIGNACIÓN!$M36-ASIGNACIÓN!$N36 -> 0.1573 | Q36: =+CONCATENATE(ASIGNACIÓN!$F36," ",ASIGNACIÓN!$G36," ",ASIGNACIÓN!$H36," ",ASIGNACIÓN!$I36," ",ASIGNACIÓN!$J36) -> CHAVARRY BARRANTES VICTOR YOVANI DICIEMBRE 2023 1501
B37: 76 | C37: MEDIMAGEN S.A.C. | D37: 45255 | E37: 7250076 | F37: COCA NUÑEZ | G37: MIGUEL | H37: DICIEMBRE | I37: 2023 | J37: 1807 | K37: SI | L37: 0.2024 | M37: 0.1935 | O37: =ASIGNACIÓN!$L37-ASIGNACIÓN!$N37 -> 0.2024 | P37: =ASIGNACIÓN!$M37-ASIGNACIÓN!$N37 -> 0.1935 | Q37: =+CONCATENATE(ASIGNACIÓN!$F37," ",ASIGNACIÓN!$G37," ",ASIGNACIÓN!$H37," ",ASIGNACIÓN!$I37," ",ASIGNACIÓN!$J37) -> COCA NUÑEZ MIGUEL DICIEMBRE 2023 1807
B38: 89 | C38: PULSO CORPORACION MEDICA S.A.C. | D38: 45255 | E38: 2005428 | F38: COLINA GARCIA | G38: MARIA YSABEL | H38: DICIEMBRE | I38: 2023 | J38: 1538 | K38: SI | L38: 0.2385 | M38: 0.2209 | O38: =ASIGNACIÓN!$L38-ASIGNACIÓN!$N38 -> 0.2385 | P38: =ASIGNACIÓN!$M38-ASIGNACIÓN!$N38 -> 0.2209 | Q38: =+CONCATENATE(ASIGNACIÓN!$F38," ",ASIGNACIÓN!$G38," ",ASIGNACIÓN!$H38," ",ASIGNACIÓN!$I38," ",ASIGNACIÓN!$J38) -> COLINA GARCIA MARIA YSABEL DICIEMBRE 2023 1538
B39: 28 | C39: CORPORACION SALUD MEDIC S.A.C. | D39: 7/12/2023 | E39: 44891495 | F39: CORDOVA MARQUEZ | G39: LUIS ANTONIO | H39: DICIEMBRE | I39: 2023 | J39: 1443 | K39: SI | L39: 0.1309 | M39: 0.1213 | O39: =ASIGNACIÓN!$L39-ASIGNACIÓN!$N39 -> 0.1309 | P39: =ASIGNACIÓN!$M39-ASIGNACIÓN!$N39 -> 0.1213 | Q39: =+CONCATENATE(ASIGNACIÓN!$F39," ",ASIGNACIÓN!$G39," ",ASIGNACIÓN!$H39," ",ASIGNACIÓN!$I39," ",ASIGNACIÓN!$J39) -> CORDOVA MARQUEZ LUIS ANTONIO DICIEMBRE 2023 1443
B40: 67 | C40: HOSPITAL METROPOLITANO S.A.C | D40: 45255 | E40: 16708968 | F40: CORNEJO ZULOETA | G40: MARIA YSABEL | H40: DICIEMBRE | I40: 2023 | J40: 1631 | K40: SI | L40: 0.181 | M40: 0.1811 | O40: =ASIGNACIÓN!$L40-ASIGNACIÓN!$N40 -> 0.181 | P40: =ASIGNACIÓN!$M40-ASIGNACIÓN!$N40 -> 0.1811 | Q40: =+CONCATENATE(ASIGNACIÓN!$F40," ",ASIGNACIÓN!$G40," ",ASIGNACIÓN!$H40," ",ASIGNACIÓN!$I40," ",ASIGNACIÓN!$J40) -> CORNEJO ZULOETA MARIA YSABEL DICIEMBRE 2023 1631
B41: 88 | C41: PULSO CORPORACION MEDICA S.A.C. | D41: 45255 | E41: 73901700 | F41: CORREA OSORIO | G41: DANIELA FERNANDA | H41: DICIEMBRE | I41: 2023 | J41: 1598 | K41: SI | L41: 0.2316 | M41: 0.225 | O41: =ASIGNACIÓN!$L41-ASIGNACIÓN!$N41 -> 0.2316 | P41: =ASIGNACIÓN!$M41-ASIGNACIÓN!$N41 -> 0.225 | Q41: =+CONCATENATE(ASIGNACIÓN!$F41," ",ASIGNACIÓN!$G41," ",ASIGNACIÓN!$H41," ",ASIGNACIÓN!$I41," ",ASIGNACIÓN!$J41) -> CORREA OSORIO DANIELA FERNANDA DICIEMBRE 2023 1598
...

Sheet FONDO
B2: 2024
B3: CODIGO | C3: ENERO | D3: FEBRERO | E3: MARZO | F3: ABRIL | G3: MAYO | H3: JUNIO | I3: JULIO | J3: AGOSTO | K3: SETIEMBRE | L3: OCTUBRE | M3: NOVIEMBRE | N3: DICIEMBRE
B4: 1796 | D4: 0.0456
B5: 1747 | E5: 0.0855 | K5: 0.12845 | M5: 0.1112
B6: 2041 | F6: 0.0902
B7: 1894 | H7: 0.0956 | L7: 0.1065 | N7: 0.08593
B8: 2050 | I8: 0.114 | J8: 0.09795
C9: =SUBTOTAL(101,C4:C8) -> #DIV/0! | D9: =SUBTOTAL(101,D4:D8) -> 0.0456 | E9: =SUBTOTAL(101,E4:E8) -> 0.0855 | F9: =SUBTOTAL(101,F4:F8) -> 0.0902 | G9: =SUBTOTAL(101,G4:G8) -> #DIV/0! | H9: =SUBTOTAL(101,H4:H8) -> 0.0956 | I9: =SUBTOTAL(101,I4:I8) -> 0.114 | J9: =SUBTOTAL(101,J4:J8) -> 0.09795 | ... M9: =SUBTOTAL(101,M4:M8) -> 0.1112
B11: 2025
B12: CODIGO | C12: ENERO | D12: FEBRERO | E12: MARZO | F12: ABRIL | G12: MAYO | H12: JUNIO | I12: JULIO | J12: AGOSTO | K12: SETIEMBRE | L12: OCTUBRE | M12: NOVIEMBRE | N12: DICIEMBRE
B13: 1796
B14: 1747
B15: 2041 | C15: 0.11736 | D15: 0.08457 | F15: 0.10284 | G15: 0.09792 | J15: 0.09728 | L15: 0.09434 | M15: 0.10405 | N15: 0.10842
B16: 1894 | H16: 0.09103
B17: 2050 | E17: 0.10714 | I17: 0.12284 | K17: 0.11186

Sheet GENERA_QR
B2: CLIENTE | C2: QR
B3: CORNEJO ZULOETA MARIA YSABEL FEBRERO 2026
